Workbook

Sheet Read Me
A1: Press Farm — Weekly Farm Supply List, Aug–Dec 2026
A3: WHAT THIS IS
A4: What to bring from the farm each week for the rest of 2026, by month. One tab per month plus a
A5: Weekly Plan Matrix showing every item's weekly quantity across all five months.
A7: SOURCE & METHOD
A8: Source: Press Farm OS database — deliveries + delivery_items (the financial source of truth), Aug 9 2025 – Aug 8 2026.
A9: Each 2026 month is projected from the same month of 2025 (seasonality-matched). Weekly qty = month total / delivery weeks in that month.
A10: BRING WEEKLY = weekly average rounded UP to a whole unit. Items delivered only 1 week last year are listed as one-offs with their month total.
A12: EXCLUSIONS (per Micheal)
A13: Deliveries under $5: 1 delivery excluded. Line items under $5: 13 lines excluded ($25.25 of $131,234.95 total — negligible).
A15: CAVEATS
A16: 2026 volumes are running ~20–35% above 2025 (52–59 item lines/month this summer vs 42–49 last summer). Treat these as floors, not ceilings.
... A18: Delivery schedule: Thu / Sat / Mon. Weekly qty = combined total across all deliveries in the week, both restaurants.

Sheet Weekly Plan Matrix
A1: Weekly Plan Matrix — bring per week, Aug–Dec 2026
A2: Numbers = units to bring each week that month (from the month tabs). 'one-off: N total' = delivered once last year — plan as a single pull. Blank = not delivered that month last year.
A4: Item | B4: Category | C4: Unit | D4: Aug | E4: Sep | F4: Oct | G4: Nov | H4: Dec | I4: Yr Revenue ($)
A5: Nasturtium | B5: Herbs & Leaves | C5: each | D5: =IFERROR(INDEX(August!$G$5:$G$49,MATCH($A5&"|"&$C5,August!$J$5:$J$49,0)),"") -> 918 | E5: =IFERROR(INDEX(September!$G$5:$G$56,MATCH($A5&"|"&$C5,September!$J$5:$J$56,0)),"") -> 924 | F5: =IFERROR(INDEX(October!$G$5:$G$48,MATCH($A5&"|"&$C5,October!$J$5:$J$48,0)),"") -> 592 | G5: =IFERROR(INDEX(November!$G$5:$G$44,MATCH($A5&"|"&$C5,November!$J$5:$J$44,0)),"") -> 395 | H5: =IFERROR(INDEX(December!$G$5:$G$33,MATCH($A5&"|"&$C5,December!$J$5:$J$33,0)),"") -> 752 | I5: 5945
A6: Peppers | B6: Fruit & Veg | C6: lbs | D6: =IFERROR(INDEX(August!$G$5:$G$49,MATCH($A6&"|"&$C6,August!$J$5:$J$49,0)),"") -> 15 | E6: =IFERROR(INDEX(September!$G$5:$G$56,MATCH($A6&"|"&$C6,September!$J$5:$J$56,0)),"") -> 70 | F6: =IFERROR(INDEX(October!$G$5:$G$48,MATCH($A6&"|"&$C6,October!$J$5:$J$48,0)),"") | G6: =IFERROR(INDEX(November!$G$5:$G$44,MATCH($A6&"|"&$C6,November!$J$5:$J$44,0)),"") | H6: =IFERROR(INDEX(December!$G$5:$G$33,MATCH($A6&"|"&$C6,December!$J$5:$J$33,0)),"") | I6: 4100
A7: Basil | B7: Herbs & Leaves | C7: LG | D7: =IFERROR(INDEX(August!$G$5:$G$49,MATCH($A7&"|"&$C7,August!$J$5:$J$49,0)),"") -> 17 | E7: =IFERROR(INDEX(September!$G$5:$G$56,MATCH($A7&"|"&$C7,September!$J$5:$J$56,0)),"") -> 22 | F7: =IFERROR(INDEX(October!$G$5:$G$48,MATCH($A7&"|"&$C7,October!$J$5:$J$48,0)),"") -> 1 | G7: =IFERROR(INDEX(November!$G$5:$G$44,MATCH($A7&"|"&$C7,November!$J$5:$J$44,0)),"") | H7: =IFERROR(INDEX(December!$G$5:$G$33,MATCH($A7&"|"&$C7,December!$J$5:$J$33,0)),"") | I7: 3612
A8: Cauliflower | B8: Fruit & Veg | C8: LG | D8: =IFERROR(INDEX(August!$G$5:$G$49,MATCH($A8&"|"&$C8,August!$J$5:$J$49,0)),"") | E8: =IFERROR(INDEX(September!$G$5:$G$56,MATCH($A8&"|"&$C8,September!$J$5:$J$56,0)),"") | F8: =IFERROR(INDEX(October!$G$5:$G$48,MATCH($A8&"|"&$C8,October!$J$5:$J$48,0)),"") -> one-off: 2 total | G8: =IFERROR(INDEX(November!$G$5:$G$44,MATCH($A8&"|"&$C8,November!$J$5:$J$44,0)),"") -> 27 | H8: =IFERROR(INDEX(December!$G$5:$G$33,MATCH($A8&"|"&$C8,December!$J$5:$J$33,0)),"") -> 6 | I8: 3280
A9: Tomatoes | B9: Fruit & Veg | C9: lbs | D9: =IFERROR(INDEX(August!$G$5:$G$49,MATCH($A9&"|"&$C9,August!$J$5:$J$49,0)),"") -> 73 | E9: =IFERROR(INDEX(September!$G$5:$G$56,MATCH($A9&"|"&$C9,September!$J$5:$J$56,0)),"") -> 75 | F9: =IFERROR(INDEX(October!$G$5:$G$48,MATCH($A9&"|"&$C9,October!$J$5:$J$48,0)),"") | G9: =IFERROR(INDEX(November!$G$5:$G$44,MATCH($A9&"|"&$C9,November!$J$5:$J$44,0)),"") | H9: =IFERROR(INDEX(December!$G$5:$G$33,MATCH($A9&"|"&$C9,December!$J$5:$J$33,0)),"") | I9: 3120
A10: Anise Hyssop | B10: Micros & Leaves | C10: LG | D10: =IFERROR(INDEX(August!$G$5:$G$49,MATCH($A10&"|"&$C10,August!$J$5:$J$49,0)),"") -> 9 | E10: =IFERROR(INDEX(September!$G$5:$G$56,MATCH($A10&"|"&$C10,September!$J$5:$J$56,0)),"") -> 17 | F10: =IFERROR(INDEX(October!$G$5:$G$48,MATCH($A10&"|"&$C10,October!$J$5:$J$48,0)),"") -> 12 | G10: =IFERROR(INDEX(November!$G$5:$G$44,MATCH($A10&"|"&$C10,November!$J$5:$J$44,0)),"") -> one-off: 8 total | H10: =IFERROR(INDEX(December!$G$5:$G$33,MATCH($A10&"|"&$C10,December!$J$5:$J$33,0)),"") | I10: 2753
A11: Carrots | B11: Fruit & Veg | C11: each | D11: =IFERROR(INDEX(August!$G$5:$G$49,MATCH($A11&"|"&$C11,August!$J$5:$J$49,0)),"") | E11: =IFERROR(INDEX(September!$G$5:$G$56,MATCH($A11&"|"&$C11,September!$J$5:$J$56,0)),"") | F11: =IFERROR(INDEX(October!$G$5:$G$48,MATCH($A11&"|"&$C11,October!$J$5:$J$48,0)),"") -> one-off: 247 total | G11: =IFERROR(INDEX(November!$G$5:$G$44,MATCH($A11&"|"&$C11,November!$J$5:$J$44,0)),"") -> 25 | H11: =IFERROR(INDEX(December!$G$5:$G$33,MATCH($A11&"|"&$C11,December!$J$5:$J$33,0)),"") -> one-off: 365 total | I11: 2581
A12: Turnip - Leaves | B12: Herbs & Leaves | C12: LG | D12: =IFERROR(INDEX(August!$G$5:$G$49,MATCH($A12&"|"&$C12,August!$J$5:$J$49,0)),"") | E12: =IFERROR(INDEX(September!$G$5:$G$56,MATCH($A12&"|"&$C12,September!$J$5:$J$56,0)),"") | F12: =IFERROR(INDEX(October!$G$5:$G$48,MATCH($A12&"|"&$C12,October!$J$5:$J$48,0)),"") | G12: =IFERROR(INDEX(November!$G$5:$G$44,MATCH($A12&"|"&$C12,November!$J$5:$J$44,0)),"") -> one-off: 100 total | H12: =IFERROR(INDEX(December!$G$5:$G$33,MATCH($A12&"|"&$C12,December!$J$5:$J$33,0)),"") | I12: 2500
A13: Squash | B13: Herbs & Leaves | C13: box | D13: =IFERROR(INDEX(August!$G$5:$G$49,MATCH($A13&"|"&$C13,August!$J$5:$J$49,0)),"") -> 4 | E13: =IFERROR(INDEX(September!$G$5:$G$56,MATCH($A13&"|"&$C13,September!$J$5:$J$56,0)),"") -> 8 | F13: =IFERROR(INDEX(October!$G$5:$G$48,MATCH($A13&"|"&$C13,October!$J$5:$J$48,0)),"") -> one-off: 2 total | G13: =IFERROR(INDEX(November!$G$5:$G$44,MATCH($A13&"|"&$C13,November!$J$5:$J$44,0)),"") | H13: =IFERROR(INDEX(December!$G$5:$G$33,MATCH($A13&"|"&$C13,December!$J$5:$J$33,0)),"") | I13: 2448
A14: Radish | B14: Flowers | C14: LG | D14: =IFERROR(INDEX(August!$G$5:$G$49,MATCH($A14&"|"&$C14,August!$J$5:$J$49,0)),"") | E14: =IFERROR(INDEX(September!$G$5:$G$56,MATCH($A14&"|"&$C14,September!$J$5:$J$56,0)),"") -> one-off: 10 total | F14: =IFERROR(INDEX(October!$G$5:$G$48,MATCH($A14&"|"&$C14,October!$J$5:$J$48,0)),"") -> 5 | G14: =IFERROR(INDEX(November!$G$5:$G$44,MATCH($A14&"|"&$C14,November!$J$5:$J$44,0)),"") -> 7 | H14: =IFERROR(INDEX(December!$G$5:$G$33,MATCH($A14&"|"&$C14,December!$J$5:$J$33,0)),"") -> 6 | I14: 2350
A15: Persimmon | B15: Fruit & Veg | C15: each | D15: =IFERROR(INDEX(August!$G$5:$G$49,MATCH($A15&"|"&$C15,August!$J$5:$J$49,0)),"") | E15: =IFERROR(INDEX(September!$G$5:$G$56,MATCH($A15&"|"&$C15,September!$J$5:$J$56,0)),"") | F15: =IFERROR(INDEX(October!$G$5:$G$48,MATCH($A15&"|"&$C15,October!$J$5:$J$48,0)),"") -> one-off: 49 total | G15: =IFERROR(INDEX(November!$G$5:$G$44,MATCH($A15&"|"&$C15,November!$J$5:$J$44,0)),"") -> one-off: 545 total | H15: =IFERROR(INDEX(December!$G$5:$G$33,MATCH($A15&"|"&$C15,December!$J$5:$J$33,0)),"") | I15: 2228
A16: Marigold | B16: Flowers | C16: SM | D16: =IFERROR(INDEX(August!$G$5:$G$49,MATCH($A16&"|"&$C16,August!$J$5:$J$49,0)),"") -> 11 | E16: =IFERROR(INDEX(September!$G$5:$G$56,MATCH($A16&"|"&$C16,September!$J$5:$J$56,0)),"") -> 14 | F16: =IFERROR(INDEX(October!$G$5:$G$48,MATCH($A16&"|"&$C16,October!$J$5:$J$48,0)),"") -> 6 | G16: =IFERROR(INDEX(November!$G$5:$G$44,MATCH($A16&"|"&$C16,November!$J$5:$J$44,0)),"") -> 4 | H16: =IFERROR(INDEX(December!$G$5:$G$33,MATCH($A16&"|"&$C16,December!$J$5:$J$33,0)),"") -> one-off: 1 total | I16: 1957
... A81: Sorrel | B81: Flowers | C81: SM | D81: =IFERROR(INDEX(August!$G$5:$G$49,MATCH($A81&"|"&$C81,August!$J$5:$J$49,0)),"") | E81: =IFERROR(INDEX(September!$G$5:$G$56,MATCH($A81&"|"&$C81,September!$J$5:$J$56,0)),"") | F81: =IFERROR(INDEX(October!$G$5:$G$48,MATCH($A81&"|"&$C81,October!$J$5:$J$48,0)),"") | G81: =IFERROR(INDEX(November!$G$5:$G$44,MATCH($A81&"|"&$C81,November!$J$5:$J$44,0)),"") -> one-off: 1 total | H81: =IFERROR(INDEX(December!$G$5:$G$33,MATCH($A81&"|"&$C81,December!$J$5:$J$33,0)),"") | I81: 6

Sheet August
A1: August 2026 — Weekly Farm Supply List
A2: Projected from Aug 2025 deliveries. Delivery weeks in source month: | E2: 4
A4: Item | B4: Category | C4: Unit | D4: Month Total (2025) | E4: Weeks Delivered | F4: Weekly Avg | G4: BRING WEEKLY | H4: Month Revenue ($) | I4: Weekly Value ($) | J4: Key
A5: WEEKLY STAPLES — bring every week
A6: Tomatoes | B6: Fruit & Veg | C6: lbs | D6: 290 | E6: 4 | F6: =ROUND(D6/$E$2,1) -> 72.5 | G6: =IF(E6>=2,CEILING(D6/$E$2,1),"one-off: "&TEXT(D6,"#,##0")&" total") -> 73 | H6: 1395 | I6: =ROUND(H6/$E$2,0) -> 349 | J6: =A6&"|"&C6 -> Tomatoes|lbs
A7: Basil | B7: Herbs & Leaves | C7: LG | D7: 67 | E7: 4 | F7: =ROUND(D7/$E$2,1) -> 16.8 | G7: =IF(E7>=2,CEILING(D7/$E$2,1),"one-off: "&TEXT(D7,"#,##0")&" total") -> 17 | H7: 1356 | I7: =ROUND(H7/$E$2,0) -> 339 | J7: =A7&"|"&C7 -> Basil|LG
A8: Nasturtium | B8: Herbs & Leaves | C8: each | D8: 3670 | E8: 4 | F8: =ROUND(D8/$E$2,1) -> 917.5 | G8: =IF(E8>=2,CEILING(D8/$E$2,1),"one-off: "&TEXT(D8,"#,##0")&" total") -> 918 | H8: 1285 | I8: =ROUND(H8/$E$2,0) -> 321 | J8: =A8&"|"&C8 -> Nasturtium|each
A9: Cucumber Leaf (1 in) | B9: Herbs & Leaves | C9: LG | D9: 66 | E9: 3 | F9: =ROUND(D9/$E$2,1) -> 16.5 | G9: =IF(E9>=2,CEILING(D9/$E$2,1),"one-off: "&TEXT(D9,"#,##0")&" total") -> 17 | H9: 990 | I9: =ROUND(H9/$E$2,0) -> 248 | J9: =A9&"|"&C9 -> Cucumber Leaf (1 in)|LG
A10: Squash | B10: Herbs & Leaves | C10: box | D10: 13 | E10: 3 | F10: =ROUND(D10/$E$2,1) -> 3.3 | G10: =IF(E10>=2,CEILING(D10/$E$2,1),"one-off: "&TEXT(D10,"#,##0")&" total") -> 4 | H10: 624 | I10: =ROUND(H10/$E$2,0) -> 156 | J10: =A10&"|"&C10 -> Squash|box
A11: Squash | B11: Herbs & Leaves | C11: LG | D11: 26 | E11: 3 | F11: =ROUND(D11/$E$2,1) -> 6.5 | G11: =IF(E11>=2,CEILING(D11/$E$2,1),"one-off: "&TEXT(D11,"#,##0")&" total") -> 7 | H11: 590 | I11: =ROUND(H11/$E$2,0) -> 148 | J11: =A11&"|"&C11 -> Squash|LG
A12: Anise Hyssop | B12: Micros & Leaves | C12: LG | D12: 35 | E12: 4 | F12: =ROUND(D12/$E$2,1) -> 8.8 | G12: =IF(E12>=2,CEILING(D12/$E$2,1),"one-off: "&TEXT(D12,"#,##0")&" total") -> 9 | H12: 525 | I12: =ROUND(H12/$E$2,0) -> 131 | J12: =A12&"|"&C12 -> Anise Hyssop|LG
A13: Marigold | B13: Flowers | C13: SM | D13: 42 | E13: 4 | F13: =ROUND(D13/$E$2,1) -> 10.5 | G13: =IF(E13>=2,CEILING(D13/$E$2,1),"one-off: "&TEXT(D13,"#,##0")&" total") -> 11 | H13: 509 | I13: =ROUND(H13/$E$2,0) -> 127 | J13: =A13&"|"&C13 -> Marigold|SM
A14: Passionfruit | B14: Fruit & Veg | C14: lbs | D14: 115 | E14: 3 | F14: =ROUND(D14/$E$2,1) -> 28.8 | G14: =IF(E14>=2,CEILING(D14/$E$2,1),"one-off: "&TEXT(D14,"#,##0")&" total") -> 29 | H14: 460 | I14: =ROUND(H14/$E$2,0) -> 115 | J14: =A14&"|"&C14 -> Passionfruit|lbs
A15: Basil | B15: Herbs & Leaves | C15: SM | D15: 33 | E15: 3 | F15: =ROUND(D15/$E$2,1) -> 8.3 | G15: =IF(E15>=2,CEILING(D15/$E$2,1),"one-off: "&TEXT(D15,"#,##0")&" total") -> 9 | H15: 396 | I15: =ROUND(H15/$E$2,0) -> 99 | J15: =A15&"|"&C15 -> Basil|SM
A16: Mint | B16: Herbs & Leaves | C16: LG | D16: 25 | E16: 3 | F16: =ROUND(D16/$E$2,1) -> 6.3 | G16: =IF(E16>=2,CEILING(D16/$E$2,1),"one-off: "&TEXT(D16,"#,##0")&" total") -> 7 | H16: 305 | I16: =ROUND(H16/$E$2,0) -> 76 | J16: =A16&"|"&C16 -> Mint|LG
A17: Egyptian Starflower | B17: Flowers | C17: SM | D17: 23 | E17: 4 | F17: =ROUND(D17/$E$2,1) -> 5.8 | G17: =IF(E17>=2,CEILING(D17/$E$2,1),"one-off: "&TEXT(D17,"#,##0")&" total") -> 6 | H17: 276 | I17: =ROUND(H17/$E$2,0) -> 69 | J17: =A17&"|"&C17 -> Egyptian Starflower|SM
... A28: Carrots | B28: Fruit & Veg | C28: LG | D28: 5 | E28: 3 | F28: =ROUND(D28/$E$2,1) -> 1.3 | G28: =IF(E28>=2,CEILING(D28/$E$2,1),"one-off: "&TEXT(D28,"#,##0")&" total") -> 2 | H28: 50 | I28: =ROUND(H28/$E$2,0) -> 13 | J28: =A28&"|"&C28 -> Carrots|LG
A29: MOST WEEKS — bring most weeks
A30: Peppers | B30: Fruit & Veg | C30: lbs | D30: 60 | E30: 2 | F30: =ROUND(D30/$E$2,1) -> 15 | G30: =IF(E30>=2,CEILING(D30/$E$2,1),"one-off: "&TEXT(D30,"#,##0")&" total") -> 15 | H30: 600 | I30: =ROUND(H30/$E$2,0) -> 150 | J30: =A30&"|"&C30 -> Peppers|lbs
A31: Figs | B31: Fruit & Veg | C31: lbs | D31: 62 | E31: 2 | F31: =ROUND(D31/$E$2,1) -> 15.5 | G31: =IF(E31>=2,CEILING(D31/$E$2,1),"one-off: "&TEXT(D31,"#,##0")&" total") -> 16 | H31: 372 | I31: =ROUND(H31/$E$2,0) -> 93 | J31: =A31&"|"&C31 -> Figs|lbs
A32: Eggplant | B32: Fruit & Veg | C32: lbs | D32: 34.5 | E32: 2 | F32: =ROUND(D32/$E$2,1) -> 8.6 | G32: =IF(E32>=2,CEILING(D32/$E$2,1),"one-off: "&TEXT(D32,"#,##0")&" total") -> 9 | H32: 276 | I32: =ROUND(H32/$E$2,0) -> 69 | J32: =A32&"|"&C32 -> Eggplant|lbs
A33: Grapes | B33: Fruit & Veg | C33: lbs | D33: 36 | E33: 2 | F33: =ROUND(D33/$E$2,1) -> 9 | G33: =IF(E33>=2,CEILING(D33/$E$2,1),"one-off: "&TEXT(D33,"#,##0")&" total") -> 9 | H33: 180 | I33: =ROUND(H33/$E$2,0) -> 45 | J33: =A33&"|"&C33 -> Grapes|lbs
A34: Tomatoes | B34: Fruit & Veg | C34: LG | D34: 15 | E34: 2 | F34: =ROUND(D34/$E$2,1) -> 3.8 | G34: =IF(E34>=2,CEILING(D34/$E$2,1),"one-off: "&TEXT(D34,"#,##0")&" total") -> 4 | H34: 150 | I34: =ROUND(H34/$E$2,0) -> 38 | J34: =A34&"|"&C34 -> Tomatoes|LG
A35: Squash Tendril | B35: Micros & Leaves | C35: LG | D35: 10 | E35: 2 | F35: =ROUND(D35/$E$2,1) -> 2.5 | G35: =IF(E35>=2,CEILING(D35/$E$2,1),"one-off: "&TEXT(D35,"#,##0")&" total") -> 3 | H35: 150 | I35: =ROUND(H35/$E$2,0) -> 38 | J35: =A35&"|"&C35 -> Squash Tendril|LG
A36: Cosmos | B36: Flowers | C36: LG | D36: 8 | E36: 2 | F36: =ROUND(D36/$E$2,1) -> 2 | G36: =IF(E36>=2,CEILING(D36/$E$2,1),"one-off: "&TEXT(D36,"#,##0")&" total") -> 2 | H36: 96 | I36: =ROUND(H36/$E$2,0) -> 24 | J36: =A36&"|"&C36 -> Cosmos|LG
A37: Aptenia | B37: Herbs & Leaves | C37: LG | D37: 4 | E37: 2 | F37: =ROUND(D37/$E$2,1) -> 1 | G37: =IF(E37>=2,CEILING(D37/$E$2,1),"one-off: "&TEXT(D37,"#,##0")&" total") -> 1 | H37: 60 | I37: =ROUND(H37/$E$2,0) -> 15 | J37: =A37&"|"&C37 -> Aptenia|LG
A38: Alyssum | B38: Flowers | C38: SM | D38: 5 | E38: 2 | F38: =ROUND(D38/$E$2,1) -> 1.3 | G38: =IF(E38>=2,CEILING(D38/$E$2,1),"one-off: "&TEXT(D38,"#,##0")&" total") -> 2 | H38: 30 | I38: =ROUND(H38/$E$2,0) -> 8 | J38: =A38&"|"&C38 -> Alyssum|SM
A39: OCCASIONAL / ONE-OFF — as available (one week last year)
A40: Lavender | B40: Herbs & Leaves | C40: each | D40: 1000 | E40: 1 | F40: =ROUND(D40/$E$2,1) -> 250 | G40: =IF(E40>=2,CEILING(D40/$E$2,1),"one-off: "&TEXT(D40,"#,##0")&" total") -> one-off: 1,000 total | H40: 100 | I40: =ROUND(H40/$E$2,0) -> 25 | J40: =A40&"|"&C40 -> Lavender|each
A41: Quince | B41: Fruit & Veg | C41: each | D41: 14 | E41: 1 | F41: =ROUND(D41/$E$2,1) -> 3.5 | G41: =IF(E41>=2,CEILING(D41/$E$2,1),"one-off: "&TEXT(D41,"#,##0")&" total") -> one-off: 14 total | H41: 90 | I41: =ROUND(H41/$E$2,0) -> 23 | J41: =A41&"|"&C41 -> Quince|each
A42: Yarrow | B42: Flowers | C42: LG | D42: 5 | E42: 1 | F42: =ROUND(D42/$E$2,1) -> 1.3 | G42: =IF(E42>=2,CEILING(D42/$E$2,1),"one-off: "&TEXT(D42,"#,##0")&" total") -> one-off: 5 total | H42: 75 | I42: =ROUND(H42/$E$2,0) -> 19 | J42: =A42&"|"&C42 -> Yarrow|LG
A43: Peaches | B43: Fruit & Veg | C43: lbs | D43: 10 | E43: 1 | F43: =ROUND(D43/$E$2,1) -> 2.5 | G43: =IF(E43>=2,CEILING(D43/$E$2,1),"one-off: "&TEXT(D43,"#,##0")&" total") -> one-off: 10 total | H43: 50 | I43: =ROUND(H43/$E$2,0) -> 13 | J43: =A43&"|"&C43 -> Peaches|lbs
A44: Blackberries | B44: Fruit & Veg | C44: LG | D44: 2 | E44: 1 | F44: =ROUND(D44/$E$2,1) -> 0.5 | G44: =IF(E44>=2,CEILING(D44/$E$2,1),"one-off: "&TEXT(D44,"#,##0")&" total") -> one-off: 2 total | H44: 48 | I44: =ROUND(H44/$E$2,0) -> 12 | J44: =A44&"|"&C44 -> Blackberries|LG
A45: Black Eyed Susans | B45: Flowers | C45: LG | D45: 2 | E45: 1 | F45: =ROUND(D45/$E$2,1) -> 0.5 | G45: =IF(E45>=2,CEILING(D45/$E$2,1),"one-off: "&TEXT(D45,"#,##0")&" total") -> one-off: 2 total | H45: 30 | I45: =ROUND(H45/$E$2,0) -> 8 | J45: =A45&"|"&C45 -> Black Eyed Susans|LG
A46: Shiso | B46: Herbs & Leaves | C46: SM | D46: 2 | E46: 1 | F46: =ROUND(D46/$E$2,1) -> 0.5 | G46: =IF(E46>=2,CEILING(D46/$E$2,1),"one-off: "&TEXT(D46,"#,##0")&" total") -> one-off: 2 total | H46: 24 | I46: =ROUND(H46/$E$2,0) -> 6 | J46: =A46&"|"&C46 -> Shiso|SM
A47: Bay Leaf | B47: Herbs & Leaves | C47: LG | D47: 1 | E47: 1 | F47: =ROUND(D47/$E$2,1) -> 0.3 | G47: =IF(E47>=2,CEILING(D47/$E$2,1),"one-off: "&TEXT(D47,"#,##0")&" total") -> one-off: 1 total | H47: 20 | I47: =ROUND(H47/$E$2,0) -> 5 | J47: =A47&"|"&C47 -> Bay Leaf|LG
A48: Field Pea Tendrils | B48: Herbs & Leaves | C48: LG | D48: 1 | E48: 1 | F48: =ROUND(D48/$E$2,1) -> 0.3 | G48: =IF(E48>=2,CEILING(D48/$E$2,1),"one-off: "&TEXT(D48,"#,##0")&" total") -> one-off: 1 total | H48: 12 | I48: =ROUND(H48/$E$2,0) -> 3 | J48: =A48&"|"&C48 -> Field Pea Tendrils|LG
A49: Apple | B49: Fruit & Veg | C49: each | D49: 8 | E49: 1 | F49: =ROUND(D49/$E$2,1) -> 2 | G49: =IF(E49>=2,CEILING(D49/$E$2,1),"one-off: "&TEXT(D49,"#,##0")&" total") -> one-off: 8 total | H49: 11 | I49: =ROUND(H49/$E$2,0) -> 3 | J49: =A49&"|"&C49 -> Apple|each
A50: MONTH TOTAL | H50: =SUM(H5:H49) -> 12753 | I50: =ROUND(H50/$E$2,0) -> 3188

Sheet September
A1: September 2026 — Weekly Farm Supply List
A2: Projected from Sep 2025 deliveries. Delivery weeks in source month: | E2: 5
A4: Item | B4: Category | C4: Unit | D4: Month Total (2025) | E4: Weeks Delivered | F4: Weekly Avg | G4: BRING WEEKLY | H4: Month Revenue ($) | I4: Weekly Value ($) | J4: Key
A5: WEEKLY STAPLES — bring every week
A6: Basil | B6: Herbs & Leaves | C6: LG | D6: 109 | E6: 5 | F6: =ROUND(D6/$E$2,1) -> 21.8 | G6: =IF(E6>=2,CEILING(D6/$E$2,1),"one-off: "&TEXT(D6,"#,##0")&" total") -> 22 | H6: 2196 | I6: =ROUND(H6/$E$2,0) -> 439 | J6: =A6&"|"&C6 -> Basil|LG
A7: Squash | B7: Herbs & Leaves | C7: box | D7: 36 | E7: 5 | F7: =ROUND(D7/$E$2,1) -> 7.2 | G7: =IF(E7>=2,CEILING(D7/$E$2,1),"one-off: "&TEXT(D7,"#,##0")&" total") -> 8 | H7: 1728 | I7: =ROUND(H7/$E$2,0) -> 346 | J7: =A7&"|"&C7 -> Squash|box
A8: Nasturtium | B8: Herbs & Leaves | C8: each | D8: 4620 | E8: 5 | F8: =ROUND(D8/$E$2,1) -> 924 | G8: =IF(E8>=2,CEILING(D8/$E$2,1),"one-off: "&TEXT(D8,"#,##0")&" total") -> 924 | H8: 1617 | I8: =ROUND(H8/$E$2,0) -> 323 | J8: =A8&"|"&C8 -> Nasturtium|each
A9: Anise Hyssop | B9: Micros & Leaves | C9: LG | D9: 82.5 | E9: 5 | F9: =ROUND(D9/$E$2,1) -> 16.5 | G9: =IF(E9>=2,CEILING(D9/$E$2,1),"one-off: "&TEXT(D9,"#,##0")&" total") -> 17 | H9: 1238 | I9: =ROUND(H9/$E$2,0) -> 248 | J9: =A9&"|"&C9 -> Anise Hyssop|LG
A10: Figs | B10: Fruit & Veg | C10: lbs | D10: 165 | E10: 5 | F10: =ROUND(D10/$E$2,1) -> 33 | G10: =IF(E10>=2,CEILING(D10/$E$2,1),"one-off: "&TEXT(D10,"#,##0")&" total") -> 33 | H10: 990 | I10: =ROUND(H10/$E$2,0) -> 198 | J10: =A10&"|"&C10 -> Figs|lbs
A11: Marigold | B11: Flowers | C11: SM | D11: 68 | E11: 5 | F11: =ROUND(D11/$E$2,1) -> 13.6 | G11: =IF(E11>=2,CEILING(D11/$E$2,1),"one-off: "&TEXT(D11,"#,##0")&" total") -> 14 | H11: 892 | I11: =ROUND(H11/$E$2,0) -> 178 | J11: =A11&"|"&C11 -> Marigold|SM
A12: Squash | B12: Herbs & Leaves | C12: LG | D12: 25 | E12: 5 | F12: =ROUND(D12/$E$2,1) -> 5 | G12: =IF(E12>=2,CEILING(D12/$E$2,1),"one-off: "&TEXT(D12,"#,##0")&" total") -> 5 | H12: 625 | I12: =ROUND(H12/$E$2,0) -> 125 | J12: =A12&"|"&C12 -> Squash|LG
A13: Passionfruit | B13: Fruit & Veg | C13: lbs | D13: 155 | E13: 5 | F13: =ROUND(D13/$E$2,1) -> 31 | G13: =IF(E13>=2,CEILING(D13/$E$2,1),"one-off: "&TEXT(D13,"#,##0")&" total") -> 31 | H13: 620 | I13: =ROUND(H13/$E$2,0) -> 124 | J13: =A13&"|"&C13 -> Passionfruit|lbs
A14: Basil | B14: Herbs & Leaves | C14: SM | D14: 42 | E14: 4 | F14: =ROUND(D14/$E$2,1) -> 8.4 | G14: =IF(E14>=2,CEILING(D14/$E$2,1),"one-off: "&TEXT(D14,"#,##0")&" total") -> 9 | H14: 504 | I14: =ROUND(H14/$E$2,0) -> 101 | J14: =A14&"|"&C14 -> Basil|SM
A15: Beans | B15: Fruit & Veg | C15: SM | D15: 31 | E15: 4 | F15: =ROUND(D15/$E$2,1) -> 6.2 | G15: =IF(E15>=2,CEILING(D15/$E$2,1),"one-off: "&TEXT(D15,"#,##0")&" total") -> 7 | H15: 465 | I15: =ROUND(H15/$E$2,0) -> 93 | J15: =A15&"|"&C15 -> Beans|SM
A16: Egyptian Starflower | B16: Flowers | C16: SM | D16: 32 | E16: 5 | F16: =ROUND(D16/$E$2,1) -> 6.4 | G16: =IF(E16>=2,CEILING(D16/$E$2,1),"one-off: "&TEXT(D16,"#,##0")&" total") -> 7 | H16: 384 | I16: =ROUND(H16/$E$2,0) -> 77 | J16: =A16&"|"&C16 -> Egyptian Starflower|SM
A17: Zinnias | B17: Flowers | C17: LG | D17: 24 | E17: 4 | F17: =ROUND(D17/$E$2,1) -> 4.8 | G17: =IF(E17>=2,CEILING(D17/$E$2,1),"one-off: "&TEXT(D17,"#,##0")&" total") -> 5 | H17: 360 | I17: =ROUND(H17/$E$2,0) -> 72 | J17: =A17&"|"&C17 -> Zinnias|LG
... A22: Alyssum | B22: Flowers | C22: SM | D22: 10 | E22: 4 | F22: =ROUND(D22/$E$2,1) -> 2 | G22: =IF(E22>=2,CEILING(D22/$E$2,1),"one-off: "&TEXT(D22,"#,##0")&" total") -> 2 | H22: 60 | I22: =ROUND(H22/$E$2,0) -> 12 | J22: =A22&"|"&C22 -> Alyssum|SM
A23: MOST WEEKS — bring most weeks
A24: Peppers | B24: Fruit & Veg | C24: lbs | D24: 350 | E24: 3 | F24: =ROUND(D24/$E$2,1) -> 70 | G24: =IF(E24>=2,CEILING(D24/$E$2,1),"one-off: "&TEXT(D24,"#,##0")&" total") -> 70 | H24: 3500 | I24: =ROUND(H24/$E$2,0) -> 700 | J24: =A24&"|"&C24 -> Peppers|lbs
A25: Tomatoes | B25: Fruit & Veg | C25: lbs | D25: 375 | E25: 3 | F25: =ROUND(D25/$E$2,1) -> 75 | G25: =IF(E25>=2,CEILING(D25/$E$2,1),"one-off: "&TEXT(D25,"#,##0")&" total") -> 75 | H25: 1725 | I25: =ROUND(H25/$E$2,0) -> 345 | J25: =A25&"|"&C25 -> Tomatoes|lbs
A26: Shiso | B26: Herbs & Leaves | C26: LG | D26: 39 | E26: 3 | F26: =ROUND(D26/$E$2,1) -> 7.8 | G26: =IF(E26>=2,CEILING(D26/$E$2,1),"one-off: "&TEXT(D26,"#,##0")&" total") -> 8 | H26: 585 | I26: =ROUND(H26/$E$2,0) -> 117 | J26: =A26&"|"&C26 -> Shiso|LG
A27: Tomatoes | B27: Fruit & Veg | C27: LG | D27: 55 | E27: 2 | F27: =ROUND(D27/$E$2,1) -> 11 | G27: =IF(E27>=2,CEILING(D27/$E$2,1),"one-off: "&TEXT(D27,"#,##0")&" total") -> 11 | H27: 550 | I27: =ROUND(H27/$E$2,0) -> 110 | J27: =A27&"|"&C27 -> Tomatoes|LG
A28: Evergreen Branches | B28: Herbs & Leaves | C28: box | D28: 21 | E28: 3 | F28: =ROUND(D28/$E$2,1) -> 4.2 | G28: =IF(E28>=2,CEILING(D28/$E$2,1),"one-off: "&TEXT(D28,"#,##0")&" total") -> 5 | H28: 420 | I28: =ROUND(H28/$E$2,0) -> 84 | J28: =A28&"|"&C28 -> Evergreen Branches|box
A29: Carrots | B29: Fruit & Veg | C29: LG | D29: 12.5 | E29: 2 | F29: =ROUND(D29/$E$2,1) -> 2.5 | G29: =IF(E29>=2,CEILING(D29/$E$2,1),"one-off: "&TEXT(D29,"#,##0")&" total") -> 3 | H29: 283 | I29: =ROUND(H29/$E$2,0) -> 57 | J29: =A29&"|"&C29 -> Carrots|LG
A30: Amaranth | B30: Micros & Leaves | C30: LG | D30: 14 | E30: 2 | F30: =ROUND(D30/$E$2,1) -> 2.8 | G30: =IF(E30>=2,CEILING(D30/$E$2,1),"one-off: "&TEXT(D30,"#,##0")&" total") -> 3 | H30: 210 | I30: =ROUND(H30/$E$2,0) -> 42 | J30: =A30&"|"&C30 -> Amaranth|LG
A31: Society Garlic | B31: Flowers | C31: LG | D31: 8.5 | E31: 3 | F31: =ROUND(D31/$E$2,1) -> 1.7 | G31: =IF(E31>=2,CEILING(D31/$E$2,1),"one-off: "&TEXT(D31,"#,##0")&" total") -> 2 | H31: 170 | I31: =ROUND(H31/$E$2,0) -> 34 | J31: =A31&"|"&C31 -> Society Garlic|LG
A32: Cosmos | B32: Flowers | C32: LG | D32: 14 | E32: 3 | F32: =ROUND(D32/$E$2,1) -> 2.8 | G32: =IF(E32>=2,CEILING(D32/$E$2,1),"one-off: "&TEXT(D32,"#,##0")&" total") -> 3 | H32: 168 | I32: =ROUND(H32/$E$2,0) -> 34 | J32: =A32&"|"&C32 -> Cosmos|LG
A33: Fennel | B33: Micros & Leaves | C33: LG | D33: 11 | E33: 3 | F33: =ROUND(D33/$E$2,1) -> 2.2 | G33: =IF(E33>=2,CEILING(D33/$E$2,1),"one-off: "&TEXT(D33,"#,##0")&" total") -> 3 | H33: 165 | I33: =ROUND(H33/$E$2,0) -> 33 | J33: =A33&"|"&C33 -> Fennel|LG
A34: Eggplant | B34: Fruit & Veg | C34: lbs | D34: 20 | E34: 2 | F34: =ROUND(D34/$E$2,1) -> 4 | G34: =IF(E34>=2,CEILING(D34/$E$2,1),"one-off: "&TEXT(D34,"#,##0")&" total") -> 4 | H34: 160 | I34: =ROUND(H34/$E$2,0) -> 32 | J34: =A34&"|"&C34 -> Eggplant|lbs
A35: Eggplant | B35: Fruit & Veg | C35: each | D35: 41 | E35: 3 | F35: =ROUND(D35/$E$2,1) -> 8.2 | G35: =IF(E35>=2,CEILING(D35/$E$2,1),"one-off: "&TEXT(D35,"#,##0")&" total") -> 9 | H35: 123 | I35: =ROUND(H35/$E$2,0) -> 25 | J35: =A35&"|"&C35 -> Eggplant|each
... A42: Aptenia | B42: Herbs & Leaves | C42: LG | D42: 2 | E42: 2 | F42: =ROUND(D42/$E$2,1) -> 0.4 | G42: =IF(E42>=2,CEILING(D42/$E$2,1),"one-off: "&TEXT(D42,"#,##0")&" total") -> 1 | H42: 30 | I42: =ROUND(H42/$E$2,0) -> 6 | J42: =A42&"|"&C42 -> Aptenia|LG
A43: OCCASIONAL / ONE-OFF — as available (one week last year)
A44: Radish | B44: Flowers | C44: LG | D44: 10 | E44: 1 | F44: =ROUND(D44/$E$2,1) -> 2 | G44: =IF(E44>=2,CEILING(D44/$E$2,1),"one-off: "&TEXT(D44,"#,##0")&" total") -> one-off: 10 total | H44: 250 | I44: =ROUND(H44/$E$2,0) -> 50 | J44: =A44&"|"&C44 -> Radish|LG
A45: Figs | B45: Fruit & Veg | C45: LG | D45: 10 | E45: 1 | F45: =ROUND(D45/$E$2,1) -> 2 | G45: =IF(E45>=2,CEILING(D45/$E$2,1),"one-off: "&TEXT(D45,"#,##0")&" total") -> one-off: 10 total | H45: 250 | I45: =ROUND(H45/$E$2,0) -> 50 | J45: =A45&"|"&C45 -> Figs|LG
A46: Peaches | B46: Fruit & Veg | C46: lbs | D46: 20 | E46: 1 | F46: =ROUND(D46/$E$2,1) -> 4 | G46: =IF(E46>=2,CEILING(D46/$E$2,1),"one-off: "&TEXT(D46,"#,##0")&" total") -> one-off: 20 total | H46: 100 | I46: =ROUND(H46/$E$2,0) -> 20 | J46: =A46&"|"&C46 -> Peaches|lbs
A47: Squash Tendril | B47: Micros & Leaves | C47: LG | D47: 6 | E47: 1 | F47: =ROUND(D47/$E$2,1) -> 1.2 | G47: =IF(E47>=2,CEILING(D47/$E$2,1),"one-off: "&TEXT(D47,"#,##0")&" total") -> one-off: 6 total | H47: 90 | I47: =ROUND(H47/$E$2,0) -> 18 | J47: =A47&"|"&C47 -> Squash Tendril|LG
A48: Olive | B48: Herbs & Leaves | C48: box | D48: 3 | E48: 1 | F48: =ROUND(D48/$E$2,1) -> 0.6 | G48: =IF(E48>=2,CEILING(D48/$E$2,1),"one-off: "&TEXT(D48,"#,##0")&" total") -> one-off: 3 total | H48: 60 | I48: =ROUND(H48/$E$2,0) -> 12 | J48: =A48&"|"&C48 -> Olive|box
A49: Wormwood | B49: Herbs & Leaves | C49: LG | D49: 1 | E49: 1 | F49: =ROUND(D49/$E$2,1) -> 0.2 | G49: =IF(E49>=2,CEILING(D49/$E$2,1),"one-off: "&TEXT(D49,"#,##0")&" total") -> one-off: 1 total | H49: 40 | I49: =ROUND(H49/$E$2,0) -> 8 | J49: =A49&"|"&C49 -> Wormwood|LG
A50: Bay Leaf | B50: Herbs & Leaves | C50: LG | D50: 2 | E50: 1 | F50: =ROUND(D50/$E$2,1) -> 0.4 | G50: =IF(E50>=2,CEILING(D50/$E$2,1),"one-off: "&TEXT(D50,"#,##0")&" total") -> one-off: 2 total | H50: 40 | I50: =ROUND(H50/$E$2,0) -> 8 | J50: =A50&"|"&C50 -> Bay Leaf|LG
A51: Pears | B51: Fruit & Veg | C51: lbs | D51: 30 | E51: 1 | F51: =ROUND(D51/$E$2,1) -> 6 | G51: =IF(E51>=2,CEILING(D51/$E$2,1),"one-off: "&TEXT(D51,"#,##0")&" total") -> one-off: 30 total | H51: 38 | I51: =ROUND(H51/$E$2,0) -> 8 | J51: =A51&"|"&C51 -> Pears|lbs
...

Sheet October
A1: October 2026 — Weekly Farm Supply List
A2: Projected from Oct 2025 deliveries. Delivery weeks in source month: | E2: 5
A4: Item | B4: Category | C4: Unit | D4: Month Total (2025) | E4: Weeks Delivered | F4: Weekly Avg | G4: BRING WEEKLY | H4: Month Revenue ($) | I4: Weekly Value ($) | J4: Key
A5: WEEKLY STAPLES — bring every week
A6: Nasturtium | B6: Herbs & Leaves | C6: each | D6: 2960 | E6: 5 | F6: =ROUND(D6/$E$2,1) -> 592 | G6: =IF(E6>=2,CEILING(D6/$E$2,1),"one-off: "&TEXT(D6,"#,##0")&" total") -> 592 | H6: 1036 | I6: =ROUND(H6/$E$2,0) -> 207 | J6: =A6&"|"&C6 -> Nasturtium|each
A7: Anise Hyssop | B7: Micros & Leaves | C7: LG | D7: 58 | E7: 4 | F7: =ROUND(D7/$E$2,1) -> 11.6 | G7: =IF(E7>=2,CEILING(D7/$E$2,1),"one-off: "&TEXT(D7,"#,##0")&" total") -> 12 | H7: 870 | I7: =ROUND(H7/$E$2,0) -> 174 | J7: =A7&"|"&C7 -> Anise Hyssop|LG
A8: Carrots | B8: Fruit & Veg | C8: LG | D8: 18 | E8: 5 | F8: =ROUND(D8/$E$2,1) -> 3.6 | G8: =IF(E8>=2,CEILING(D8/$E$2,1),"one-off: "&TEXT(D8,"#,##0")&" total") -> 4 | H8: 385 | I8: =ROUND(H8/$E$2,0) -> 77 | J8: =A8&"|"&C8 -> Carrots|LG
A9: Marigold | B9: Flowers | C9: SM | D9: 28 | E9: 5 | F9: =ROUND(D9/$E$2,1) -> 5.6 | G9: =IF(E9>=2,CEILING(D9/$E$2,1),"one-off: "&TEXT(D9,"#,##0")&" total") -> 6 | H9: 359 | I9: =ROUND(H9/$E$2,0) -> 72 | J9: =A9&"|"&C9 -> Marigold|SM
A10: New Zealand Spinach | B10: Fruit & Veg | C10: LG | D10: 20 | E10: 5 | F10: =ROUND(D10/$E$2,1) -> 4 | G10: =IF(E10>=2,CEILING(D10/$E$2,1),"one-off: "&TEXT(D10,"#,##0")&" total") -> 4 | H10: 300 | I10: =ROUND(H10/$E$2,0) -> 60 | J10: =A10&"|"&C10 -> New Zealand Spinach|LG
A11: Society Garlic | B11: Flowers | C11: LG | D11: 4.5 | E11: 4 | F11: =ROUND(D11/$E$2,1) -> 0.9 | G11: =IF(E11>=2,CEILING(D11/$E$2,1),"one-off: "&TEXT(D11,"#,##0")&" total") -> 1 | H11: 90 | I11: =ROUND(H11/$E$2,0) -> 18 | J11: =A11&"|"&C11 -> Society Garlic|LG
A12: MOST WEEKS — bring most weeks
A13: Forget-Me-Nots | B13: Flowers | C13: SM | D13: 75 | E13: 2 | F13: =ROUND(D13/$E$2,1) -> 15 | G13: =IF(E13>=2,CEILING(D13/$E$2,1),"one-off: "&TEXT(D13,"#,##0")&" total") -> 15 | H13: 900 | I13: =ROUND(H13/$E$2,0) -> 180 | J13: =A13&"|"&C13 -> Forget-Me-Nots|SM
A14: Radish | B14: Flowers | C14: LG | D14: 24 | E14: 3 | F14: =ROUND(D14/$E$2,1) -> 4.8 | G14: =IF(E14>=2,CEILING(D14/$E$2,1),"one-off: "&TEXT(D14,"#,##0")&" total") -> 5 | H14: 600 | I14: =ROUND(H14/$E$2,0) -> 120 | J14: =A14&"|"&C14 -> Radish|LG
A15: Figs | B15: Fruit & Veg | C15: lbs | D15: 90 | E15: 3 | F15: =ROUND(D15/$E$2,1) -> 18 | G15: =IF(E15>=2,CEILING(D15/$E$2,1),"one-off: "&TEXT(D15,"#,##0")&" total") -> 18 | H15: 540 | I15: =ROUND(H15/$E$2,0) -> 108 | J15: =A15&"|"&C15 -> Figs|lbs
A16: Mustard Flowers | B16: Flowers | C16: LG | D16: 21 | E16: 3 | F16: =ROUND(D16/$E$2,1) -> 4.2 | G16: =IF(E16>=2,CEILING(D16/$E$2,1),"one-off: "&TEXT(D16,"#,##0")&" total") -> 5 | H16: 412 | I16: =ROUND(H16/$E$2,0) -> 82 | J16: =A16&"|"&C16 -> Mustard Flowers|LG
A17: Beans | B17: Fruit & Veg | C17: LG | D17: 17 | E17: 3 | F17: =ROUND(D17/$E$2,1) -> 3.4 | G17: =IF(E17>=2,CEILING(D17/$E$2,1),"one-off: "&TEXT(D17,"#,##0")&" total") -> 4 | H17: 204 | I17: =ROUND(H17/$E$2,0) -> 41 | J17: =A17&"|"&C17 -> Beans|LG
A18: Egyptian Starflower | B18: Flowers | C18: SM | D18: 15 | E18: 3 | F18: =ROUND(D18/$E$2,1) -> 3 | G18: =IF(E18>=2,CEILING(D18/$E$2,1),"one-off: "&TEXT(D18,"#,##0")&" total") -> 3 | H18: 180 | I18: =ROUND(H18/$E$2,0) -> 36 | J18: =A18&"|"&C18 -> Egyptian Starflower|SM
A19: Rose Geranium | B19: Flowers | C19: LG | D19: 11 | E19: 2 | F19: =ROUND(D19/$E$2,1) -> 2.2 | G19: =IF(E19>=2,CEILING(D19/$E$2,1),"one-off: "&TEXT(D19,"#,##0")&" total") -> 3 | H19: 176 | I19: =ROUND(H19/$E$2,0) -> 35 | J19: =A19&"|"&C19 -> Rose Geranium|LG
A20: Alyssum | B20: Flowers | C20: SM | D20: 29 | E20: 3 | F20: =ROUND(D20/$E$2,1) -> 5.8 | G20: =IF(E20>=2,CEILING(D20/$E$2,1),"one-off: "&TEXT(D20,"#,##0")&" total") -> 6 | H20: 174 | I20: =ROUND(H20/$E$2,0) -> 35 | J20: =A20&"|"&C20 -> Alyssum|SM
A21: Basil | B21: Herbs & Leaves | C21: SM | D21: 11 | E21: 3 | F21: =ROUND(D21/$E$2,1) -> 2.2 | G21: =IF(E21>=2,CEILING(D21/$E$2,1),"one-off: "&TEXT(D21,"#,##0")&" total") -> 3 | H21: 132 | I21: =ROUND(H21/$E$2,0) -> 26 | J21: =A21&"|"&C21 -> Basil|SM
A22: Zinnias | B22: Flowers | C22: LG | D22: 6 | E22: 3 | F22: =ROUND(D22/$E$2,1) -> 1.2 | G22: =IF(E22>=2,CEILING(D22/$E$2,1),"one-off: "&TEXT(D22,"#,##0")&" total") -> 2 | H22: 90 | I22: =ROUND(H22/$E$2,0) -> 18 | J22: =A22&"|"&C22 -> Zinnias|LG
A23: Beans | B23: Fruit & Veg | C23: SM | D23: 6 | E23: 2 | F23: =ROUND(D23/$E$2,1) -> 1.2 | G23: =IF(E23>=2,CEILING(D23/$E$2,1),"one-off: "&TEXT(D23,"#,##0")&" total") -> 2 | H23: 90 | I23: =ROUND(H23/$E$2,0) -> 18 | J23: =A23&"|"&C23 -> Beans|SM
A24: Basil | B24: Herbs & Leaves | C24: LG | D24: 5 | E24: 3 | F24: =ROUND(D24/$E$2,1) -> 1 | G24: =IF(E24>=2,CEILING(D24/$E$2,1),"one-off: "&TEXT(D24,"#,##0")&" total") -> 1 | H24: 60 | I24: =ROUND(H24/$E$2,0) -> 12 | J24: =A24&"|"&C24 -> Basil|LG
... A29: Radish | B29: Flowers | C29: SM | D29: 2 | E29: 2 | F29: =ROUND(D29/$E$2,1) -> 0.4 | G29: =IF(E29>=2,CEILING(D29/$E$2,1),"one-off: "&TEXT(D29,"#,##0")&" total") -> 1 | H29: 20 | I29: =ROUND(H29/$E$2,0) -> 4 | J29: =A29&"|"&C29 -> Radish|SM
A30: OCCASIONAL / ONE-OFF — as available (one week last year)
A31: Carrots | B31: Fruit & Veg | C31: each | D31: 247 | E31: 1 | F31: =ROUND(D31/$E$2,1) -> 49.4 | G31: =IF(E31>=2,CEILING(D31/$E$2,1),"one-off: "&TEXT(D31,"#,##0")&" total") -> one-off: 247 total | H31: 865 | I31: =ROUND(H31/$E$2,0) -> 173 | J31: =A31&"|"&C31 -> Carrots|each
A32: Persimmon | B32: Fruit & Veg | C32: each | D32: 49 | E32: 1 | F32: =ROUND(D32/$E$2,1) -> 9.8 | G32: =IF(E32>=2,CEILING(D32/$E$2,1),"one-off: "&TEXT(D32,"#,##0")&" total") -> one-off: 49 total | H32: 184 | I32: =ROUND(H32/$E$2,0) -> 37 | J32: =A32&"|"&C32 -> Persimmon|each
A33: Figs | B33: Fruit & Veg | C33: LG | D33: 5 | E33: 1 | F33: =ROUND(D33/$E$2,1) -> 1 | G33: =IF(E33>=2,CEILING(D33/$E$2,1),"one-off: "&TEXT(D33,"#,##0")&" total") -> one-off: 5 total | H33: 125 | I33: =ROUND(H33/$E$2,0) -> 25 | J33: =A33&"|"&C33 -> Figs|LG
A34: Squash | B34: Herbs & Leaves | C34: box | D34: 2 | E34: 1 | F34: =ROUND(D34/$E$2,1) -> 0.4 | G34: =IF(E34>=2,CEILING(D34/$E$2,1),"one-off: "&TEXT(D34,"#,##0")&" total") -> one-off: 2 total | H34: 96 | I34: =ROUND(H34/$E$2,0) -> 19 | J34: =A34&"|"&C34 -> Squash|box
A35: Mustard Flowers | B35: Flowers | C35: lbs | D35: 10 | E35: 1 | F35: =ROUND(D35/$E$2,1) -> 2 | G35: =IF(E35>=2,CEILING(D35/$E$2,1),"one-off: "&TEXT(D35,"#,##0")&" total") -> one-off: 10 total | H35: 80 | I35: =ROUND(H35/$E$2,0) -> 16 | J35: =A35&"|"&C35 -> Mustard Flowers|lbs
A36: Samples | B36: Herbs & Leaves | C36: LG | D36: 6 | E36: 1 | F36: =ROUND(D36/$E$2,1) -> 1.2 | G36: =IF(E36>=2,CEILING(D36/$E$2,1),"one-off: "&TEXT(D36,"#,##0")&" total") -> one-off: 6 total | H36: 72 | I36: =ROUND(H36/$E$2,0) -> 14 | J36: =A36&"|"&C36 -> Samples|LG
A37: Kale | B37: Herbs & Leaves | C37: LG | D37: 3 | E37: 1 | F37: =ROUND(D37/$E$2,1) -> 0.6 | G37: =IF(E37>=2,CEILING(D37/$E$2,1),"one-off: "&TEXT(D37,"#,##0")&" total") -> one-off: 3 total | H37: 60 | I37: =ROUND(H37/$E$2,0) -> 12 | J37: =A37&"|"&C37 -> Kale|LG
A38: Cauliflower | B38: Fruit & Veg | C38: LG | D38: 2 | E38: 1 | F38: =ROUND(D38/$E$2,1) -> 0.4 | G38: =IF(E38>=2,CEILING(D38/$E$2,1),"one-off: "&TEXT(D38,"#,##0")&" total") -> one-off: 2 total | H38: 40 | I38: =ROUND(H38/$E$2,0) -> 8 | J38: =A38&"|"&C38 -> Cauliflower|LG
A39: Mustard Leaves | B39: Herbs & Leaves | C39: LG | D39: 2 | E39: 1 | F39: =ROUND(D39/$E$2,1) -> 0.4 | G39: =IF(E39>=2,CEILING(D39/$E$2,1),"one-off: "&TEXT(D39,"#,##0")&" total") -> one-off: 2 total | H39: 39 | I39: =ROUND(H39/$E$2,0) -> 8 | J39: =A39&"|"&C39 -> Mustard Leaves|LG
A40: Fennel | B40: Micros & Leaves | C40: LG | D40: 2 | E40: 1 | F40: =ROUND(D40/$E$2,1) -> 0.4 | G40: =IF(E40>=2,CEILING(D40/$E$2,1),"one-off: "&TEXT(D40,"#,##0")&" total") -> one-off: 2 total | H40: 30 | I40: =ROUND(H40/$E$2,0) -> 6 | J40: =A40&"|"&C40 -> Fennel|LG
A41: Squash | B41: Herbs & Leaves | C41: LG | D41: 1 | E41: 1 | F41: =ROUND(D41/$E$2,1) -> 0.2 | G41: =IF(E41>=2,CEILING(D41/$E$2,1),"one-off: "&TEXT(D41,"#,##0")&" total") -> one-off: 1 total | H41: 25 | I41: =ROUND(H41/$E$2,0) -> 5 | J41: =A41&"|"&C41 -> Squash|LG
A42: Evergreen Branches | B42: Herbs & Leaves | C42: box | D42: 1 | E42: 1 | F42: =ROUND(D42/$E$2,1) -> 0.2 | G42: =IF(E42>=2,CEILING(D42/$E$2,1),"one-off: "&TEXT(D42,"#,##0")&" total") -> one-off: 1 total | H42: 20 | I42: =ROUND(H42/$E$2,0) -> 4 | J42: =A42&"|"&C42 -> Evergreen Branches|box
... A48: Sage | B48: Herbs & Leaves | C48: LG | D48: 1 | E48: 1 | F48: =ROUND(D48/$E$2,1) -> 0.2 | G48: =IF(E48>=2,CEILING(D48/$E$2,1),"one-off: "&TEXT(D48,"#,##0")&" total") -> one-off: 1 total | H48: 12 | I48: =ROUND(H48/$E$2,0) -> 2 | J48: =A48&"|"&C48 -> Sage|LG
A49: MONTH TOTAL | H49: =SUM(H5:H48) -> 8536 | I49: =ROUND(H49/$E$2,0) -> 1707

Sheet November
A1: November 2026 — Weekly Farm Supply List
A2: Projected from Nov 2025 deliveries. Delivery weeks in source month: | E2: 5
A4: Item | B4: Category | C4: Unit | D4: Month Total (2025) | E4: Weeks Delivered | F4: Weekly Avg | G4: BRING WEEKLY | H4: Month Revenue ($) | I4: Weekly Value ($) | J4: Key
A5: WEEKLY STAPLES — bring every week
A6: Radish | B6: Flowers | C6: LG | D6: 34 | E6: 4 | F6: =ROUND(D6/$E$2,1) -> 6.8 | G6: =IF(E6>=2,CEILING(D6/$E$2,1),"one-off: "&TEXT(D6,"#,##0")&" total") -> 7 | H6: 850 | I6: =ROUND(H6/$E$2,0) -> 170 | J6: =A6&"|"&C6 -> Radish|LG
A7: Nasturtium | B7: Herbs & Leaves | C7: each | D7: 1975 | E7: 5 | F7: =ROUND(D7/$E$2,1) -> 395 | G7: =IF(E7>=2,CEILING(D7/$E$2,1),"one-off: "&TEXT(D7,"#,##0")&" total") -> 395 | H7: 691 | I7: =ROUND(H7/$E$2,0) -> 138 | J7: =A7&"|"&C7 -> Nasturtium|each
A8: Kale | B8: Herbs & Leaves | C8: LG | D8: 34 | E8: 5 | F8: =ROUND(D8/$E$2,1) -> 6.8 | G8: =IF(E8>=2,CEILING(D8/$E$2,1),"one-off: "&TEXT(D8,"#,##0")&" total") -> 7 | H8: 680 | I8: =ROUND(H8/$E$2,0) -> 136 | J8: =A8&"|"&C8 -> Kale|LG
A9: Mustard Flowers | B9: Flowers | C9: LG | D9: 30.5 | E9: 4 | F9: =ROUND(D9/$E$2,1) -> 6.1 | G9: =IF(E9>=2,CEILING(D9/$E$2,1),"one-off: "&TEXT(D9,"#,##0")&" total") -> 7 | H9: 602 | I9: =ROUND(H9/$E$2,0) -> 120 | J9: =A9&"|"&C9 -> Mustard Flowers|LG
A10: Aptenia | B10: Herbs & Leaves | C10: LG | D10: 29 | E10: 4 | F10: =ROUND(D10/$E$2,1) -> 5.8 | G10: =IF(E10>=2,CEILING(D10/$E$2,1),"one-off: "&TEXT(D10,"#,##0")&" total") -> 6 | H10: 435 | I10: =ROUND(H10/$E$2,0) -> 87 | J10: =A10&"|"&C10 -> Aptenia|LG
A11: Alyssum | B11: Flowers | C11: SM | D11: 39 | E11: 5 | F11: =ROUND(D11/$E$2,1) -> 7.8 | G11: =IF(E11>=2,CEILING(D11/$E$2,1),"one-off: "&TEXT(D11,"#,##0")&" total") -> 8 | H11: 234 | I11: =ROUND(H11/$E$2,0) -> 47 | J11: =A11&"|"&C11 -> Alyssum|SM
A12: Marigold | B12: Flowers | C12: SM | D12: 17 | E12: 4 | F12: =ROUND(D12/$E$2,1) -> 3.4 | G12: =IF(E12>=2,CEILING(D12/$E$2,1),"one-off: "&TEXT(D12,"#,##0")&" total") -> 4 | H12: 182 | I12: =ROUND(H12/$E$2,0) -> 36 | J12: =A12&"|"&C12 -> Marigold|SM
A13: Beans | B13: Fruit & Veg | C13: LG | D13: 12 | E13: 4 | F13: =ROUND(D13/$E$2,1) -> 2.4 | G13: =IF(E13>=2,CEILING(D13/$E$2,1),"one-off: "&TEXT(D13,"#,##0")&" total") -> 3 | H13: 144 | I13: =ROUND(H13/$E$2,0) -> 29 | J13: =A13&"|"&C13 -> Beans|LG
A14: Carrots | B14: Fruit & Veg | C14: LG | D14: 7 | E14: 5 | F14: =ROUND(D14/$E$2,1) -> 1.4 | G14: =IF(E14>=2,CEILING(D14/$E$2,1),"one-off: "&TEXT(D14,"#,##0")&" total") -> 2 | H14: 84 | I14: =ROUND(H14/$E$2,0) -> 17 | J14: =A14&"|"&C14 -> Carrots|LG
A15: Radish | B15: Flowers | C15: SM | D15: 8 | E15: 4 | F15: =ROUND(D15/$E$2,1) -> 1.6 | G15: =IF(E15>=2,CEILING(D15/$E$2,1),"one-off: "&TEXT(D15,"#,##0")&" total") -> 2 | H15: 80 | I15: =ROUND(H15/$E$2,0) -> 16 | J15: =A15&"|"&C15 -> Radish|SM
A16: MOST WEEKS — bring most weeks
A17: Cauliflower | B17: Fruit & Veg | C17: LG | D17: 133 | E17: 3 | F17: =ROUND(D17/$E$2,1) -> 26.6 | G17: =IF(E17>=2,CEILING(D17/$E$2,1),"one-off: "&TEXT(D17,"#,##0")&" total") -> 27 | H17: 2660 | I17: =ROUND(H17/$E$2,0) -> 532 | J17: =A17&"|"&C17 -> Cauliflower|LG
A18: Carrots | B18: Fruit & Veg | C18: each | D18: 125 | E18: 2 | F18: =ROUND(D18/$E$2,1) -> 25 | G18: =IF(E18>=2,CEILING(D18/$E$2,1),"one-off: "&TEXT(D18,"#,##0")&" total") -> 25 | H18: 438 | I18: =ROUND(H18/$E$2,0) -> 88 | J18: =A18&"|"&C18 -> Carrots|each
A19: New Zealand Spinach | B19: Fruit & Veg | C19: LG | D19: 8.5 | E19: 2 | F19: =ROUND(D19/$E$2,1) -> 1.7 | G19: =IF(E19>=2,CEILING(D19/$E$2,1),"one-off: "&TEXT(D19,"#,##0")&" total") -> 2 | H19: 128 | I19: =ROUND(H19/$E$2,0) -> 26 | J19: =A19&"|"&C19 -> New Zealand Spinach|LG
A20: Broccoli | B20: Fruit & Veg | C20: LG | D20: 6 | E20: 2 | F20: =ROUND(D20/$E$2,1) -> 1.2 | G20: =IF(E20>=2,CEILING(D20/$E$2,1),"one-off: "&TEXT(D20,"#,##0")&" total") -> 2 | H20: 113 | I20: =ROUND(H20/$E$2,0) -> 23 | J20: =A20&"|"&C20 -> Broccoli|LG
A21: Buckwheat | B21: Flowers | C21: SM | D21: 9 | E21: 2 | F21: =ROUND(D21/$E$2,1) -> 1.8 | G21: =IF(E21>=2,CEILING(D21/$E$2,1),"one-off: "&TEXT(D21,"#,##0")&" total") -> 2 | H21: 90 | I21: =ROUND(H21/$E$2,0) -> 18 | J21: =A21&"|"&C21 -> Buckwheat|SM
A22: Egyptian Starflower | B22: Flowers | C22: SM | D22: 6 | E22: 3 | F22: =ROUND(D22/$E$2,1) -> 1.2 | G22: =IF(E22>=2,CEILING(D22/$E$2,1),"one-off: "&TEXT(D22,"#,##0")&" total") -> 2 | H22: 72 | I22: =ROUND(H22/$E$2,0) -> 14 | J22: =A22&"|"&C22 -> Egyptian Starflower|SM
A23: Rosemary | B23: Herbs & Leaves | C23: each | D23: 350 | E23: 3 | F23: =ROUND(D23/$E$2,1) -> 70 | G23: =IF(E23>=2,CEILING(D23/$E$2,1),"one-off: "&TEXT(D23,"#,##0")&" total") -> 70 | H23: 70 | I23: =ROUND(H23/$E$2,0) -> 14 | J23: =A23&"|"&C23 -> Rosemary|each
A24: Sorrel | B24: Flowers | C24: LG | D24: 2 | E24: 2 | F24: =ROUND(D24/$E$2,1) -> 0.4 | G24: =IF(E24>=2,CEILING(D24/$E$2,1),"one-off: "&TEXT(D24,"#,##0")&" total") -> 1 | H24: 60 | I24: =ROUND(H24/$E$2,0) -> 12 | J24: =A24&"|"&C24 -> Sorrel|LG
A25: Mint | B25: Herbs & Leaves | C25: LG | D25: 4.5 | E25: 2 | F25: =ROUND(D25/$E$2,1) -> 0.9 | G25: =IF(E25>=2,CEILING(D25/$E$2,1),"one-off: "&TEXT(D25,"#,##0")&" total") -> 1 | H25: 58 | I25: =ROUND(H25/$E$2,0) -> 12 | J25: =A25&"|"&C25 -> Mint|LG
A26: Field Pea Tendrils | B26: Herbs & Leaves | C26: LG | D26: 4 | E26: 3 | F26: =ROUND(D26/$E$2,1) -> 0.8 | G26: =IF(E26>=2,CEILING(D26/$E$2,1),"one-off: "&TEXT(D26,"#,##0")&" total") -> 1 | H26: 48 | I26: =ROUND(H26/$E$2,0) -> 10 | J26: =A26&"|"&C26 -> Field Pea Tendrils|LG
A27: Zinnias | B27: Flowers | C27: LG | D27: 3 | E27: 2 | F27: =ROUND(D27/$E$2,1) -> 0.6 | G27: =IF(E27>=2,CEILING(D27/$E$2,1),"one-off: "&TEXT(D27,"#,##0")&" total") -> 1 | H27: 45 | I27: =ROUND(H27/$E$2,0) -> 9 | J27: =A27&"|"&C27 -> Zinnias|LG
A28: Cress | B28: Micros & Leaves | C28: LG | D28: 3 | E28: 2 | F28: =ROUND(D28/$E$2,1) -> 0.6 | G28: =IF(E28>=2,CEILING(D28/$E$2,1),"one-off: "&TEXT(D28,"#,##0")&" total") -> 1 | H28: 45 | I28: =ROUND(H28/$E$2,0) -> 9 | J28: =A28&"|"&C28 -> Cress|LG
... A32: Forget-Me-Nots | B32: Flowers | C32: SM | D32: 2 | E32: 2 | F32: =ROUND(D32/$E$2,1) -> 0.4 | G32: =IF(E32>=2,CEILING(D32/$E$2,1),"one-off: "&TEXT(D32,"#,##0")&" total") -> 1 | H32: 24 | I32: =ROUND(H32/$E$2,0) -> 5 | J32: =A32&"|"&C32 -> Forget-Me-Nots|SM
A33: OCCASIONAL / ONE-OFF — as available (one week last year)
A34: Turnip - Leaves | B34: Herbs & Leaves | C34: LG | D34: 100 | E34: 1 | F34: =ROUND(D34/$E$2,1) -> 20 | G34: =IF(E34>=2,CEILING(D34/$E$2,1),"one-off: "&TEXT(D34,"#,##0")&" total") -> one-off: 100 total | H34: 2500 | I34: =ROUND(H34/$E$2,0) -> 500 | J34: =A34&"|"&C34 -> Turnip - Leaves|LG
A35: Persimmon | B35: Fruit & Veg | C35: each | D35: 545 | E35: 1 | F35: =ROUND(D35/$E$2,1) -> 109 | G35: =IF(E35>=2,CEILING(D35/$E$2,1),"one-off: "&TEXT(D35,"#,##0")&" total") -> one-off: 545 total | H35: 2044 | I35: =ROUND(H35/$E$2,0) -> 409 | J35: =A35&"|"&C35 -> Persimmon|each
A36: Cabbage | B36: Herbs & Leaves | C36: LG | D36: 20 | E36: 1 | F36: =ROUND(D36/$E$2,1) -> 4 | G36: =IF(E36>=2,CEILING(D36/$E$2,1),"one-off: "&TEXT(D36,"#,##0")&" total") -> one-off: 20 total | H36: 300 | I36: =ROUND(H36/$E$2,0) -> 60 | J36: =A36&"|"&C36 -> Cabbage|LG
A37: Anise Hyssop | B37: Micros & Leaves | C37: LG | D37: 8 | E37: 1 | F37: =ROUND(D37/$E$2,1) -> 1.6 | G37: =IF(E37>=2,CEILING(D37/$E$2,1),"one-off: "&TEXT(D37,"#,##0")&" total") -> one-off: 8 total | H37: 120 | I37: =ROUND(H37/$E$2,0) -> 24 | J37: =A37&"|"&C37 -> Anise Hyssop|LG
A38: Samples | B38: Herbs & Leaves | C38: LG | D38: 6 | E38: 1 | F38: =ROUND(D38/$E$2,1) -> 1.2 | G38: =IF(E38>=2,CEILING(D38/$E$2,1),"one-off: "&TEXT(D38,"#,##0")&" total") -> one-off: 6 total | H38: 72 | I38: =ROUND(H38/$E$2,0) -> 14 | J38: =A38&"|"&C38 -> Samples|LG
A39: Bay Leaf | B39: Herbs & Leaves | C39: LG | D39: 2 | E39: 1 | F39: =ROUND(D39/$E$2,1) -> 0.4 | G39: =IF(E39>=2,CEILING(D39/$E$2,1),"one-off: "&TEXT(D39,"#,##0")&" total") -> one-off: 2 total | H39: 40 | I39: =ROUND(H39/$E$2,0) -> 8 | J39: =A39&"|"&C39 -> Bay Leaf|LG
A40: Society Garlic | B40: Flowers | C40: LG | D40: 1 | E40: 1 | F40: =ROUND(D40/$E$2,1) -> 0.2 | G40: =IF(E40>=2,CEILING(D40/$E$2,1),"one-off: "&TEXT(D40,"#,##0")&" total") -> one-off: 1 total | H40: 20 | I40: =ROUND(H40/$E$2,0) -> 4 | J40: =A40&"|"&C40 -> Society Garlic|LG
A41: Chrysanthemum | B41: Herbs & Leaves | C41: LG | D41: 1 | E41: 1 | F41: =ROUND(D41/$E$2,1) -> 0.2 | G41: =IF(E41>=2,CEILING(D41/$E$2,1),"one-off: "&TEXT(D41,"#,##0")&" total") -> one-off: 1 total | H41: 18 | I41: =ROUND(H41/$E$2,0) -> 4 | J41: =A41&"|"&C41 -> Chrysanthemum|LG
A42: Chickweed | B42: Herbs & Leaves | C42: LG | D42: 1 | E42: 1 | F42: =ROUND(D42/$E$2,1) -> 0.2 | G42: =IF(E42>=2,CEILING(D42/$E$2,1),"one-off: "&TEXT(D42,"#,##0")&" total") -> one-off: 1 total | H42: 12 | I42: =ROUND(H42/$E$2,0) -> 2 | J42: =A42&"|"&C42 -> Chickweed|LG
A43: Oxalis Flowers | B43: Flowers | C43: SM | D43: 2 | E43: 1 | F43: =ROUND(D43/$E$2,1) -> 0.4 | G43: =IF(E43>=2,CEILING(D43/$E$2,1),"one-off: "&TEXT(D43,"#,##0")&" total") -> one-off: 2 total | H43: 12 | I43: =ROUND(H43/$E$2,0) -> 2 | J43: =A43&"|"&C43 -> Oxalis Flowers|SM
A44: Sorrel | B44: Flowers | C44: SM | D44: 1 | E44: 1 | F44: =ROUND(D44/$E$2,1) -> 0.2 | G44: =IF(E44>=2,CEILING(D44/$E$2,1),"one-off: "&TEXT(D44,"#,##0")&" total") -> one-off: 1 total | H44: 6 | I44: =ROUND(H44/$E$2,0) -> 1 | J44: =A44&"|"&C44 -> Sorrel|SM
...

Sheet December
A1: December 2026 — Weekly Farm Supply List
A2: Projected from Dec 2025 deliveries. Delivery weeks in source month: | E2: 5
A4: Item | B4: Category | C4: Unit | D4: Month Total (2025) | E4: Weeks Delivered | F4: Weekly Avg | G4: BRING WEEKLY | H4: Month Revenue ($) | I4: Weekly Value ($) | J4: Key
A5: WEEKLY STAPLES — bring every week
A6: Nasturtium | B6: Herbs & Leaves | C6: each | D6: 3760 | E6: 5 | F6: =ROUND(D6/$E$2,1) -> 752 | G6: =IF(E6>=2,CEILING(D6/$E$2,1),"one-off: "&TEXT(D6,"#,##0")&" total") -> 752 | H6: 1316 | I6: =ROUND(H6/$E$2,0) -> 263 | J6: =A6&"|"&C6 -> Nasturtium|each
A7: Mustard Flowers | B7: Flowers | C7: LG | D7: 41 | E7: 5 | F7: =ROUND(D7/$E$2,1) -> 8.2 | G7: =IF(E7>=2,CEILING(D7/$E$2,1),"one-off: "&TEXT(D7,"#,##0")&" total") -> 9 | H7: 780 | I7: =ROUND(H7/$E$2,0) -> 156 | J7: =A7&"|"&C7 -> Mustard Flowers|LG
A8: Radish | B8: Flowers | C8: LG | D8: 26 | E8: 4 | F8: =ROUND(D8/$E$2,1) -> 5.2 | G8: =IF(E8>=2,CEILING(D8/$E$2,1),"one-off: "&TEXT(D8,"#,##0")&" total") -> 6 | H8: 650 | I8: =ROUND(H8/$E$2,0) -> 130 | J8: =A8&"|"&C8 -> Radish|LG
A9: Cauliflower | B9: Fruit & Veg | C9: LG | D9: 29 | E9: 4 | F9: =ROUND(D9/$E$2,1) -> 5.8 | G9: =IF(E9>=2,CEILING(D9/$E$2,1),"one-off: "&TEXT(D9,"#,##0")&" total") -> 6 | H9: 580 | I9: =ROUND(H9/$E$2,0) -> 116 | J9: =A9&"|"&C9 -> Cauliflower|LG
A10: Kale | B10: Herbs & Leaves | C10: LG | D10: 16 | E10: 4 | F10: =ROUND(D10/$E$2,1) -> 3.2 | G10: =IF(E10>=2,CEILING(D10/$E$2,1),"one-off: "&TEXT(D10,"#,##0")&" total") -> 4 | H10: 320 | I10: =ROUND(H10/$E$2,0) -> 64 | J10: =A10&"|"&C10 -> Kale|LG
A11: Cress | B11: Micros & Leaves | C11: LG | D11: 10 | E11: 4 | F11: =ROUND(D11/$E$2,1) -> 2 | G11: =IF(E11>=2,CEILING(D11/$E$2,1),"one-off: "&TEXT(D11,"#,##0")&" total") -> 2 | H11: 150 | I11: =ROUND(H11/$E$2,0) -> 30 | J11: =A11&"|"&C11 -> Cress|LG
A12: Mint | B12: Herbs & Leaves | C12: LG | D12: 7 | E12: 4 | F12: =ROUND(D12/$E$2,1) -> 1.4 | G12: =IF(E12>=2,CEILING(D12/$E$2,1),"one-off: "&TEXT(D12,"#,##0")&" total") -> 2 | H12: 80 | I12: =ROUND(H12/$E$2,0) -> 16 | J12: =A12&"|"&C12 -> Mint|LG
A13: Oxalis Flowers | B13: Flowers | C13: SM | D13: 11 | E13: 4 | F13: =ROUND(D13/$E$2,1) -> 2.2 | G13: =IF(E13>=2,CEILING(D13/$E$2,1),"one-off: "&TEXT(D13,"#,##0")&" total") -> 3 | H13: 66 | I13: =ROUND(H13/$E$2,0) -> 13 | J13: =A13&"|"&C13 -> Oxalis Flowers|SM
A14: MOST WEEKS — bring most weeks
A15: Aptenia | B15: Herbs & Leaves | C15: LG | D15: 14 | E15: 3 | F15: =ROUND(D15/$E$2,1) -> 2.8 | G15: =IF(E15>=2,CEILING(D15/$E$2,1),"one-off: "&TEXT(D15,"#,##0")&" total") -> 3 | H15: 210 | I15: =ROUND(H15/$E$2,0) -> 42 | J15: =A15&"|"&C15 -> Aptenia|LG
A16: Alyssum | B16: Flowers | C16: SM | D16: 33 | E16: 3 | F16: =ROUND(D16/$E$2,1) -> 6.6 | G16: =IF(E16>=2,CEILING(D16/$E$2,1),"one-off: "&TEXT(D16,"#,##0")&" total") -> 7 | H16: 198 | I16: =ROUND(H16/$E$2,0) -> 40 | J16: =A16&"|"&C16 -> Alyssum|SM
A17: Passionfruit | B17: Fruit & Veg | C17: LG | D17: 12 | E17: 2 | F17: =ROUND(D17/$E$2,1) -> 2.4 | G17: =IF(E17>=2,CEILING(D17/$E$2,1),"one-off: "&TEXT(D17,"#,##0")&" total") -> 3 | H17: 144 | I17: =ROUND(H17/$E$2,0) -> 29 | J17: =A17&"|"&C17 -> Passionfruit|LG
A18: Chrysanthemum | B18: Herbs & Leaves | C18: LG | D18: 5 | E18: 3 | F18: =ROUND(D18/$E$2,1) -> 1 | G18: =IF(E18>=2,CEILING(D18/$E$2,1),"one-off: "&TEXT(D18,"#,##0")&" total") -> 1 | H18: 90 | I18: =ROUND(H18/$E$2,0) -> 18 | J18: =A18&"|"&C18 -> Chrysanthemum|LG
A19: Forget-Me-Nots | B19: Flowers | C19: SM | D19: 7 | E19: 3 | F19: =ROUND(D19/$E$2,1) -> 1.4 | G19: =IF(E19>=2,CEILING(D19/$E$2,1),"one-off: "&TEXT(D19,"#,##0")&" total") -> 2 | H19: 84 | I19: =ROUND(H19/$E$2,0) -> 17 | J19: =A19&"|"&C19 -> Forget-Me-Nots|SM
A20: Broccoli | B20: Fruit & Veg | C20: LG | D20: 4 | E20: 3 | F20: =ROUND(D20/$E$2,1) -> 0.8 | G20: =IF(E20>=2,CEILING(D20/$E$2,1),"one-off: "&TEXT(D20,"#,##0")&" total") -> 1 | H20: 65 | I20: =ROUND(H20/$E$2,0) -> 13 | J20: =A20&"|"&C20 -> Broccoli|LG
A21: Beans | B21: Fruit & Veg | C21: LG | D21: 4 | E21: 2 | F21: =ROUND(D21/$E$2,1) -> 0.8 | G21: =IF(E21>=2,CEILING(D21/$E$2,1),"one-off: "&TEXT(D21,"#,##0")&" total") -> 1 | H21: 48 | I21: =ROUND(H21/$E$2,0) -> 10 | J21: =A21&"|"&C21 -> Beans|LG
A22: Radish | B22: Flowers | C22: SM | D22: 4 | E22: 2 | F22: =ROUND(D22/$E$2,1) -> 0.8 | G22: =IF(E22>=2,CEILING(D22/$E$2,1),"one-off: "&TEXT(D22,"#,##0")&" total") -> 1 | H22: 40 | I22: =ROUND(H22/$E$2,0) -> 8 | J22: =A22&"|"&C22 -> Radish|SM
A23: Bay Leaf | B23: Herbs & Leaves | C23: LG | D23: 2 | E23: 2 | F23: =ROUND(D23/$E$2,1) -> 0.4 | G23: =IF(E23>=2,CEILING(D23/$E$2,1),"one-off: "&TEXT(D23,"#,##0")&" total") -> 1 | H23: 40 | I23: =ROUND(H23/$E$2,0) -> 8 | J23: =A23&"|"&C23 -> Bay Leaf|LG
A24: Carrots | B24: Fruit & Veg | C24: LG | D24: 3 | E24: 3 | F24: =ROUND(D24/$E$2,1) -> 0.6 | G24: =IF(E24>=2,CEILING(D24/$E$2,1),"one-off: "&TEXT(D24,"#,##0")&" total") -> 1 | H24: 36 | I24: =ROUND(H24/$E$2,0) -> 7 | J24: =A24&"|"&C24 -> Carrots|LG
A25: Rosemary | B25: Herbs & Leaves | C25: each | D25: 100 | E25: 2 | F25: =ROUND(D25/$E$2,1) -> 20 | G25: =IF(E25>=2,CEILING(D25/$E$2,1),"one-off: "&TEXT(D25,"#,##0")&" total") -> 20 | H25: 20 | I25: =ROUND(H25/$E$2,0) -> 4 | J25: =A25&"|"&C25 -> Rosemary|each
A26: OCCASIONAL / ONE-OFF — as available (one week last year)
A27: Carrots | B27: Fruit & Veg | C27: each | D27: 365 | E27: 1 | F27: =ROUND(D27/$E$2,1) -> 73 | G27: =IF(E27>=2,CEILING(D27/$E$2,1),"one-off: "&TEXT(D27,"#,##0")&" total") -> one-off: 365 total | H27: 1278 | I27: =ROUND(H27/$E$2,0) -> 256 | J27: =A27&"|"&C27 -> Carrots|each
A28: Dianthus | B28: Flowers | C28: LG | D28: 5 | E28: 1 | F28: =ROUND(D28/$E$2,1) -> 1 | G28: =IF(E28>=2,CEILING(D28/$E$2,1),"one-off: "&TEXT(D28,"#,##0")&" total") -> one-off: 5 total | H28: 75 | I28: =ROUND(H28/$E$2,0) -> 15 | J28: =A28&"|"&C28 -> Dianthus|LG
A29: Mint | B29: Herbs & Leaves | C29: SM | D29: 6 | E29: 1 | F29: =ROUND(D29/$E$2,1) -> 1.2 | G29: =IF(E29>=2,CEILING(D29/$E$2,1),"one-off: "&TEXT(D29,"#,##0")&" total") -> one-off: 6 total | H29: 60 | I29: =ROUND(H29/$E$2,0) -> 12 | J29: =A29&"|"&C29 -> Mint|SM
A30: Fennel | B30: Micros & Leaves | C30: LG | D30: 3 | E30: 1 | F30: =ROUND(D30/$E$2,1) -> 0.6 | G30: =IF(E30>=2,CEILING(D30/$E$2,1),"one-off: "&TEXT(D30,"#,##0")&" total") -> one-off: 3 total | H30: 35 | I30: =ROUND(H30/$E$2,0) -> 7 | J30: =A30&"|"&C30 -> Fennel|LG
A31: Evergreen Branches | B31: Herbs & Leaves | C31: box | D31: 1 | E31: 1 | F31: =ROUND(D31/$E$2,1) -> 0.2 | G31: =IF(E31>=2,CEILING(D31/$E$2,1),"one-off: "&TEXT(D31,"#,##0")&" total") -> one-off: 1 total | H31: 20 | I31: =ROUND(H31/$E$2,0) -> 4 | J31: =A31&"|"&C31 -> Evergreen Branches|box
A32: Marigold | B32: Flowers | C32: SM | D32: 1 | E32: 1 | F32: =ROUND(D32/$E$2,1) -> 0.2 | G32: =IF(E32>=2,CEILING(D32/$E$2,1),"one-off: "&TEXT(D32,"#,##0")&" total") -> one-off: 1 total | H32: 15 | I32: =ROUND(H32/$E$2,0) -> 3 | J32: =A32&"|"&C32 -> Marigold|SM
A33: Chickweed | B33: Herbs & Leaves | C33: LG | D33: 1 | E33: 1 | F33: =ROUND(D33/$E$2,1) -> 0.2 | G33: =IF(E33>=2,CEILING(D33/$E$2,1),"one-off: "&TEXT(D33,"#,##0")&" total") -> one-off: 1 total | H33: 12 | I33: =ROUND(H33/$E$2,0) -> 2 | J33: =A33&"|"&C33 -> Chickweed|LG
A34: MONTH TOTAL | H34: =SUM(H5:H33) -> 6412 | I34: =ROUND(H34/$E$2,0) -> 1282
